<?xml version="1.0" encoding="utf-8"?>
<!-- This URDF was automatically created by SolidWorks to URDF Exporter! Originally created by Stephen Brawner (brawner@gmail.com) 
     Commit Version: 1.6.0-4-g7f85cfe  Build Version: 1.6.7995.38578
     For more information, please see http://wiki.ros.org/sw_urdf_exporter -->
<robot name="desktop-arm" xmlns:xacro="http://ros.org/wiki/xacro">
  <link name="base_link">
    <inertial>
      <origin xyz="0.032063 -0.15615 0.060422" rpy="0 0 0" />
      <mass value="0.64235" />
      <inertia ixx="0.0015157" ixy="-2.584E-07" ixz="-1.4498E-07" iyy="0.0015152" iyz="6.003E-08" izz="0.002624" />
    </inertial>
    <visual>
      <origin xyz="0 0 0" rpy="0 0 0" />
      <geometry>
        <mesh filename="package://desktop_arm_description/meshes/base_link.STL" />
      </geometry>
      <material name="">
        <color rgba="0.79216 0.81961 0.93333 1" />
      </material>
    </visual>
    <collision>
      <origin xyz="0 0 0" rpy="0 0 0" />
      <geometry>
        <mesh filename="package://desktop_arm_description/meshes/base_link.STL" />
      </geometry>
    </collision>
  </link>
  <link name="link_1">
    <inertial>
      <origin xyz="1.32150942671883E-05 0.0840712343150202 -0.000226674153144618" rpy="0 0 0" />
      <mass value="2.06098242470071" />
      <inertia ixx="0.00723151267076472" ixy="8.50060421303669E-08" ixz="-0.000493369007400085" iyy="0.00643124857029598" iyz="8.77055790859003E-07" izz="0.00833376606191396" />
    </inertial>
    <visual>
      <origin xyz="0 0 0" rpy="0 0 0" />
      <geometry>
        <mesh filename="package://desktop_arm_description/meshes/link_1.STL" />
      </geometry>
      <material name="">
        <color rgba="0.792156862745098 0.819607843137255 0.933333333333333 1" />
      </material>
    </visual>
    <collision>
      <origin xyz="0 0 0" rpy="0 0 0" />
      <geometry>
        <mesh filename="package://desktop_arm_description/meshes/link_1.STL" />
      </geometry>
    </collision>
  </link>
  <joint name="joint_1" type="revolute">
    <origin xyz="0 0 0" rpy="1.5707963267949 0 0.70838946909971" />
    <parent link="base_link" />
    <child link="link_1" />
    <axis xyz="0 1 0" />
    <limit lower="-1.3" upper="1.3" effort="0" velocity="0" />
  </joint>
  <link name="link_2">
    <inertial>
      <origin xyz="0.01789 0.058654 -0.05071" rpy="0 0 0" />
      <mass value="1.9263" />
      <inertia ixx="0.0047439" ixy="-0.00037569" ixz="0.00028127" iyy="0.0038445" iyz="0.00096517" izz="0.0041374" />
    </inertial>
    <visual>
      <origin xyz="0 0 0" rpy="0 0 0" />
      <geometry>
        <mesh filename="package://desktop_arm_description/meshes/link_2.STL" />
      </geometry>
      <material name="">
        <color rgba="0.79216 0.81961 0.93333 1" />
      </material>
    </visual>
    <collision>
      <origin xyz="0 0 0" rpy="0 0 0" />
      <geometry>
        <mesh filename="package://desktop_arm_description/meshes/link_2.STL" />
      </geometry>
    </collision>
  </link>
  <joint name="joint_2" type="revolute">
    <origin xyz="0 0.1655 0" rpy="0.288567690879059 -0.0158462661982318 0.10895820907763" />
    <parent link="link_1" />
    <child link="link_2" />
    <axis xyz="0.934125217802764 0 0.356945482482884" />
    <limit lower="-1.3" upper="1.3" effort="0" velocity="0" />
  </joint>
  <link name="link_3">
    <inertial>
      <origin xyz="0.0139481789637224 0.0146668632687502 -0.0359246194913087" rpy="0 0 0" />
      <mass value="0.725230105179457" />
      <inertia ixx="0.00179957485676987" ixy="-0.000147553492540297" ixz="0.000456755493645833" iyy="0.00154110709734523" iyz="0.00038828009924826" izz="0.000772747821956818" />
    </inertial>
    <visual>
      <origin xyz="0 0 0" rpy="0 0 0" />
      <geometry>
        <mesh filename="package://desktop_arm_description/meshes/link_3.STL" />
      </geometry>
      <material name="">
        <color rgba="0.792156862745098 0.819607843137255 0.933333333333333 1" />
      </material>
    </visual>
    <collision>
      <origin xyz="0 0 0" rpy="0 0 0" />
      <geometry>
        <mesh filename="package://desktop_arm_description/meshes/link_3.STL" />
      </geometry>
    </collision>
  </link>
  <joint name="joint_3" type="revolute">
    <origin xyz="0.0533123755144546 0.163058763880744 -0.139518320956508" rpy="-0.28856769087906 -0.0158462661982266 -0.10895820907763" />
    <parent link="link_2" />
    <child link="link_3" />
    <axis xyz="0.934125217802763 0 0.356945482482886" />
    <limit lower="-1.3" upper="1.3" effort="0" velocity="0" />
  </joint>
  <link name="link_4">
    <inertial>
      <origin xyz="0.0184305955320793 0.0223219439403024 -0.0554419139160314" rpy="0 0 0" />
      <mass value="0.332133737054409" />
      <inertia ixx="0.000492451112757706" ixy="-2.8044250164716E-05" ixz="6.1771366365912E-05" iyy="0.000556523835973434" iyz="0.000103934198616861" izz="0.00036921676282899" />
    </inertial>
    <visual>
      <origin xyz="0 0 0" rpy="0 0 0" />
      <geometry>
        <mesh filename="package://desktop_arm_description/meshes/link_4.STL" />
      </geometry>
      <material name="">
        <color rgba="0.792156862745098 0.819607843137255 0.933333333333333 1" />
      </material>
    </visual>
    <collision>
      <origin xyz="0 0 0" rpy="0 0 0" />
      <geometry>
        <mesh filename="package://desktop_arm_description/meshes/link_4.STL" />
      </geometry>
    </collision>
  </link>
  <joint name="joint_4" type="revolute">
    <origin xyz="0.039132 0.040964 -0.10092" rpy="-0.81888 0.68462 3.0043" />
    <parent link="link_3" />
    <child link="link_4" />
    <axis xyz="0.33384 0.35396 -0.87365" />
    <limit lower="-1.3" upper="1.3" effort="0" velocity="0" />
  </joint>
  <link name="link_5">
    <inertial>
      <origin xyz="0.0003711 -0.0019484 -0.0032986" rpy="0 0 0" />
      <mass value="0.15863" />
      <inertia ixx="0.0001012" ixy="-3.4148E-06" ixz="1.3247E-05" iyy="6.4478E-05" iyz="-7.7884E-06" izz="6.1328E-05" />
    </inertial>
    <visual>
      <origin xyz="0 0 0" rpy="0 0 0" />
      <geometry>
        <mesh filename="package://desktop_arm_description/meshes/link_5.STL" />
      </geometry>
      <material name="">
        <color rgba="0.79216 0.81961 0.93333 1" />
      </material>
    </visual>
    <collision>
      <origin xyz="0 0 0" rpy="0 0 0" />
      <geometry>
        <mesh filename="package://desktop_arm_description/meshes/link_5.STL" />
      </geometry>
    </collision>
  </link>
  <joint name="joint_5" type="revolute">
    <origin xyz="0.035644 0.037793 -0.09328" rpy="0.99317 -0.27115 0.21303" />
    <parent link="link_4" />
    <child link="link_5" />
    <axis xyz="0.9426 -0.13293 0.30633" />
    <limit lower="-1.3" upper="1.3" effort="0" velocity="0" />
  </joint>
  <link name="end_effector">
    <inertial>
      <origin xyz="0.14241 0.38652 -0.15071" rpy="0 0 0" />
      <mass value="0.069485" />
      <inertia ixx="1.6525E-05" ixy="2.5479E-06" ixz="-8.6292E-07" iyy="2.184E-05" iyz="-5.1516E-06" izz="1.5862E-05" />
    </inertial>
    <visual>
      <origin xyz="0 0 0" rpy="0 0 0" />
      <geometry>
        <mesh filename="package://desktop_arm_description/meshes/end_effector.STL" />
      </geometry>
      <material name="">
        <color rgba="0.79216 0.81961 0.93333 1" />
      </material>
    </visual>
    <collision>
      <origin xyz="0 0 0" rpy="0 0 0" />
      <geometry>
        <mesh filename="package://desktop_arm_description/meshes/end_effector.STL" />
      </geometry>
    </collision>
  </link>
  <joint name="joint_6" type="revolute">
    <origin xyz="0.17605 0.29813 -0.29218" rpy="1.1615 0.33095 -2.9233" />
    <parent link="link_5" />
    <child link="end_effector" />
    <axis xyz="0 0 0" />
    <limit lower="-1.3" upper="1.3" effort="0" velocity="0" />
  </joint>
  <link name="tool0"/>
  <joint name="joint6-tool0" type="fixed">
    <parent link="end_effector"/>
    <child link="tool0"/>
    <origin rpy="0 0.1 0" xyz="0 0 0"/>
  </joint>
  <link name="base"/>
  <joint name="base_link-base" type="fixed">
    <origin rpy="0 0 0" xyz="0 0 0"/>
    <parent link="base_link"/>
    <child link="base"/>
  </joint>
</robot>

